<?xml version="1.0" ?>
<!-- =================================================================================== -->
<!-- |    This document was autogenerated by xacro from manipulator_pusher2d.xacro     | -->
<!-- |    EDITING THIS FILE BY HAND IS NOT RECOMMENDED                                 | -->
<!-- =================================================================================== -->
<!-- Manipulator 2D robot (based on Revolute-Revolute Manipulator) -->
<robot name="manipulator2d" xmlns:xacro="http://www.ros.org/wiki/xacro">
  <!--&lt;!&ndash; Import all Gazebo-customization elements, including Gazebo colors &ndash;&gt;-->
  <!--<xacro:include filename="$(find manipulator2d_description)/urdf/manipulator2d.gazebo" />-->
  <!--&lt;!&ndash; Import Rviz colors &ndash;&gt;-->
  <!--<xacro:include filename="$(find manipulator2d_description)/urdf/materials.xacro" />-->
  <!-- Used for fixing robot to Gazebo 'base_link' -->
  <link name="world"/>
  <!--<joint name="fixed" type="fixed">-->
  <!--<parent link="world"/>-->
  <!--<child link="link1"/>-->
  <!--<origin xyz="0 0 ${base_z}" rpy="0 0 0"/>-->
  <!--</joint>-->
  <joint name="fixed" type="fixed">
    <parent link="world"/>
    <child link="base_link"/>
    <origin rpy="0 0 0" xyz="0 0 0.0"/>
  </joint>
  <link name="base_link">
    <collision>
      <origin rpy="0 0 0" xyz="0 0 0.025"/>
      <geometry>
        <cylinder length="0.03" radius="0.01"/>
      </geometry>
    </collision>
    <visual>
      <origin rpy="0 0 0" xyz="0 0 0.025"/>
      <geometry>
        <cylinder length="0.03" radius="0.01"/>
      </geometry>
      <material name="black"/>
    </visual>
    <inertial>
      <origin rpy="0 0 0" xyz="0 0 0.025"/>
      <mass value="2.46615023307"/>
      <inertia ixx="0.000575435054383" ixy="0.0" ixz="0.0" iyy="0.000575435054383" iyz="0.0" izz="0.000123307511653"/>
    </inertial>
  </link>
  <joint name="joint0" type="revolute">
    <parent link="base_link"/>
    <child link="coupler0"/>
    <origin rpy="0 0 0" xyz="0 0 0.03"/>
    <limit effort="100.0" lower="-2.5" upper="2.5" velocity="3.14159265"/>
    <axis xyz="0 0 1"/>
    <dynamics damping="1.0"/>
  </joint>
  <link name="coupler0">
    <collision>
      <origin rpy="0 0 0" xyz="0 0 0"/>
      <geometry>
        <!--<sphere radius="${radius_axel}"/>-->
        <cylinder length="0.05" radius="0.045"/>
      </geometry>
      <material name="white"/>
    </collision>
    <visual>
      <origin rpy="0 0 0" xyz="0 0 0"/>
      <geometry>
        <!--<sphere radius="${radius_axel}"/>-->
        <cylinder length="0.05" radius="0.045"/>
      </geometry>
      <material name="white"/>
    </visual>
    <inertial>
      <origin rpy="0 0 0" xyz="0 0 0"/>
      <mass value="0.001"/>
      <inertia ixx="0.001" ixy="0.0" ixz="0.0" iyy="0.001" iyz="0.0" izz="0.001"/>
    </inertial>
  </link>
  <joint name="coupler_joint0" type="fixed">
    <parent link="coupler0"/>
    <child link="link1"/>
    <origin rpy="0 0 0" xyz="0 0 0"/>
  </joint>
  <!-- Base Link -->
  <link name="link1">
    <collision>
      <origin rpy="1.57079632679 0 1.57079632679" xyz="0.1 0 0"/>
      <geometry>
        <cylinder length="0.2" radius="0.025"/>
      </geometry>
    </collision>
    <visual>
      <origin rpy="1.57079632679 0 1.57079632679" xyz="0.1 0 0"/>
      <geometry>
        <cylinder length="0.2" radius="0.025"/>
      </geometry>
      <material name="blue"/>
    </visual>
    <inertial>
      <origin rpy="1.57079632679 0 1.57079632679" xyz="0.1 0 0"/>
      <mass value="0.848230016469"/>
      <inertia ixx="0.0029599693283" ixy="0.0" ixz="0.0" iyy="0.0029599693283" iyz="0.0" izz="0.000265071880147"/>
    </inertial>
  </link>
  <joint name="joint1" type="revolute">
    <parent link="link1"/>
    <child link="coupler1"/>
    <origin rpy="0 0 0" xyz="0.235 0 0"/>
    <limit effort="100.0" lower="-2.3213" upper="2.3" velocity="3.14159265"/>
    <axis xyz="0 0 1"/>
    <dynamics damping="1.0"/>
  </joint>
  <link name="coupler1">
    <collision>
      <origin rpy="0 0 0" xyz="0 0 0"/>
      <geometry>
        <cylinder length="0.05" radius="0.045"/>
      </geometry>
      <material name="white"/>
    </collision>
    <visual>
      <origin rpy="0 0 0" xyz="0 0 0"/>
      <geometry>
        <cylinder length="0.05" radius="0.045"/>
      </geometry>
      <material name="white"/>
    </visual>
    <inertial>
      <origin rpy="0 0 0" xyz="0 0 0"/>
      <mass value="0.001"/>
      <inertia ixx="0.001" ixy="0.0" ixz="0.0" iyy="0.001" iyz="0.0" izz="0.001"/>
    </inertial>
  </link>
  <joint name="coupler_joint1" type="fixed">
    <parent link="coupler1"/>
    <child link="link2"/>
    <origin rpy="0 0 0" xyz="0.035 0 0"/>
  </joint>
  <!--Middle Link-->
  <link name="link2">
    <collision>
      <origin rpy="1.57079632679 0 1.57079632679" xyz="0.1 0 0"/>
      <geometry>
        <cylinder length="0.2" radius="0.025"/>
      </geometry>
    </collision>
    <visual>
      <origin rpy="1.57079632679 0 1.57079632679" xyz="0.1 0 0"/>
      <geometry>
        <cylinder length="0.2" radius="0.025"/>
      </geometry>
      <material name="blue"/>
    </visual>
    <inertial>
      <origin rpy="1.57079632679 0 1.57079632679" xyz="0.1 0 0"/>
      <mass value="0.848230016469"/>
      <inertia ixx="0.0029599693283" ixy="0.0" ixz="0.0" iyy="0.0029599693283" iyz="0.0" izz="0.000265071880147"/>
    </inertial>
  </link>
  <joint name="joint2" type="revolute">
    <parent link="link2"/>
    <child link="coupler2"/>
    <origin rpy="0 0 0" xyz="0.235 0 0"/>
    <limit effort="100.0" lower="-2.3213" upper="2.3" velocity="3.14159265"/>
    <axis xyz="0 0 1"/>
    <dynamics damping="1.0"/>
  </joint>
  <link name="coupler2">
    <collision>
      <origin rpy="0 0 0" xyz="0 0 0"/>
      <geometry>
        <cylinder length="0.05" radius="0.045"/>
      </geometry>
      <material name="white"/>
    </collision>
    <visual>
      <origin rpy="0 0 0" xyz="0 0 0"/>
      <geometry>
        <cylinder length="0.05" radius="0.045"/>
      </geometry>
      <material name="white"/>
    </visual>
    <inertial>
      <origin rpy="0 0 0" xyz="0 0 0"/>
      <mass value="0.001"/>
      <inertia ixx="0.001" ixy="0.0" ixz="0.0" iyy="0.001" iyz="0.0" izz="0.001"/>
    </inertial>
  </link>
  <joint name="coupler_joint2" type="fixed">
    <parent link="coupler2"/>
    <child link="link3"/>
    <origin rpy="0 0 0" xyz="0.035 0 0"/>
  </joint>
  <!--Top Link-->
  <link name="link3">
    <collision>
      <origin rpy="1.57079632679 0 1.57079632679" xyz="0.1 0 0"/>
      <geometry>
        <cylinder length="0.2" radius="0.025"/>
      </geometry>
    </collision>
    <visual>
      <origin rpy="1.57079632679 0 1.57079632679" xyz="0.1 0 0"/>
      <geometry>
        <cylinder length="0.2" radius="0.025"/>
      </geometry>
      <material name="blue"/>
    </visual>
    <inertial>
      <origin rpy="1.57079632679 0 1.57079632679" xyz="0.1 0 0"/>
      <mass value="0.848230016469"/>
      <inertia ixx="0.0029599693283" ixy="0.0" ixz="0.0" iyy="0.0029599693283" iyz="0.0" izz="0.000265071880147"/>
    </inertial>
  </link>
  <joint name="gripper_joint" type="fixed">
    <parent link="link3"/>
    <child link="gripper"/>
    <origin rpy="0 0 0" xyz="0.2 0 0"/>
  </joint>
  <link name="gripper">
    <collision>
      <origin rpy="1.57079632679 0 1.57079632679" xyz="0.0075 0 0"/>
      <geometry>
        <box size="0.2 0.05 0.015"/>
      </geometry>
      <material name="white"/>
    </collision>
    <collision>
      <origin rpy="1.57079632679 0 1.57079632679" xyz="0.0675 0.09 0"/>
      <geometry>
        <box size="0.02 0.05 0.105"/>
      </geometry>
      <material name="white"/>
    </collision>
    <collision>
      <origin rpy="1.57079632679 0 1.57079632679" xyz="0.0675 -0.09 0"/>
      <geometry>
        <box size="0.02 0.05 0.105"/>
      </geometry>
      <material name="white"/>
    </collision>
    <visual>
      <origin rpy="1.57079632679 0 1.57079632679" xyz="0.0075 0 0"/>
      <geometry>
        <box size="0.2 0.05 0.015"/>
      </geometry>
      <material name="white"/>
    </visual>
    <visual>
      <origin rpy="1.57079632679 0 1.57079632679" xyz="0.0675 0.09 0"/>
      <geometry>
        <box size="0.02 0.05 0.105"/>
      </geometry>
      <material name="white"/>
    </visual>
    <visual>
      <origin rpy="1.57079632679 0 1.57079632679" xyz="0.0675 -0.09 0"/>
      <geometry>
        <box size="0.02 0.05 0.105"/>
      </geometry>
      <material name="white"/>
    </visual>
    <inertial>
      <origin rpy="0 0 0" xyz="0 0 0"/>
      <mass value="0.1"/>
      <inertia ixx="0.001" ixy="0.0" ixz="0.0" iyy="0.001" iyz="0.0" izz="0.001"/>
    </inertial>
  </link>
  <joint name="gripper_center_joint" type="fixed">
    <parent link="gripper"/>
    <child link="gripper_center"/>
    <origin rpy="0 0 0" xyz="0.07 0 0"/>
  </joint>
  <link name="gripper_center">
    <!--<visual>-->
    <!--<origin xyz="0 0 0" rpy="0 0 0"/>-->
    <!--<geometry>-->
    <!--<cylinder length="${height_axel}" radius="${radius_axel}"/>-->
    <!--</geometry>-->
    <!--<material name="white"/>-->
    <!--</visual>-->
    <inertial>
      <origin rpy="0 0 0" xyz="0 0 0"/>
      <mass value="0.001"/>
      <inertia ixx="0.001" ixy="0.0" ixz="0.0" iyy="0.001" iyz="0.0" izz="0.001"/>
    </inertial>
  </link>
  <!--<joint name="hokuyo_joint" type="fixed">-->
  <!--<axis xyz="0 1 0" />-->
  <!--<origin xyz="0 0 ${height3 - axel_offset/2}" rpy="0 0 0"/>-->
  <!--<parent link="link3"/>-->
  <!--<child link="hokuyo_link"/>-->
  <!--</joint>-->
  <!--&lt;!&ndash; Hokuyo Laser &ndash;&gt;-->
  <!--<link name="hokuyo_link">-->
  <!--<collision>-->
  <!--<origin xyz="0 0 0" rpy="0 0 0"/>-->
  <!--<geometry>-->
  <!--<box size="0.1 0.1 0.1"/>-->
  <!--</geometry>-->
  <!--</collision>-->
  <!--<visual>-->
  <!--<origin xyz="0 0 0" rpy="0 0 0"/>-->
  <!--<geometry>-->
  <!--<mesh filename="package://manipulator2d_description/meshes/hokuyo.dae"/>-->
  <!--</geometry>-->
  <!--</visual>-->
  <!--<inertial>-->
  <!--<mass value="1e-5" />-->
  <!--<origin xyz="0 0 0" rpy="0 0 0"/>-->
  <!--<inertia ixx="1e-6" ixy="0" ixz="0" iyy="1e-6" iyz="0" izz="1e-6" />-->
  <!--</inertial>-->
  <!--</link>-->
  <!--<joint name="camera_joint" type="fixed">-->
  <!--<axis xyz="0 1 0" />-->
  <!--<origin xyz="${camera_x} ${camera_y} ${camera_z}" rpy="0 ${PI/2} ${PI/2}"/>-->
  <!--<parent link="base_link"/>-->
  <!--<child link="camera_link"/>-->
  <!--</joint>-->
  <!-- Camera -->
  <!--<link name="camera_link">-->
  <!--&lt;!&ndash;<collision>&ndash;&gt;-->
  <!--&lt;!&ndash;<origin xyz="0 0 0" rpy="0 0 0"/>&ndash;&gt;-->
  <!--&lt;!&ndash;<geometry>&ndash;&gt;-->
  <!--&lt;!&ndash;<box size="${camera_link} ${camera_link} ${camera_link}"/>&ndash;&gt;-->
  <!--&lt;!&ndash;</geometry>&ndash;&gt;-->
  <!--&lt;!&ndash;</collision>&ndash;&gt;-->
  <!--&lt;!&ndash;<visual>&ndash;&gt;-->
  <!--&lt;!&ndash;<origin xyz="0 0 0" rpy="0 0 0"/>&ndash;&gt;-->
  <!--&lt;!&ndash;<geometry>&ndash;&gt;-->
  <!--&lt;!&ndash;<box size="${camera_link} ${camera_link} ${camera_link}"/>&ndash;&gt;-->
  <!--&lt;!&ndash;</geometry>&ndash;&gt;-->
  <!--&lt;!&ndash;<material name="red"/>&ndash;&gt;-->
  <!--&lt;!&ndash;</visual>&ndash;&gt;-->
  <!--&lt;!&ndash;<inertial>&ndash;&gt;-->
  <!--&lt;!&ndash;<mass value="1e-5" />&ndash;&gt;-->
  <!--&lt;!&ndash;<origin xyz="0 0 0" rpy="0 0 0"/>&ndash;&gt;-->
  <!--&lt;!&ndash;<inertia ixx="1e-6" ixy="0" ixz="0" iyy="1e-6" iyz="0" izz="1e-6" />&ndash;&gt;-->
  <!--&lt;!&ndash;</inertial>&ndash;&gt;-->
  <!--</link>-->
  <!-- generate an optical frame http://www.ros.org/reps/rep-0103.html#suffix-frames
      so that ros and opencv can operate on the camera frame correctly -->
  <!--<joint name="camera_optical_joint" type="fixed">-->
  <!--&lt;!&ndash; these values have to be these values otherwise the gazebo camera image-->
  <!--won't be aligned properly with the frame it is supposedly originating from &ndash;&gt;-->
  <!--<origin xyz="0 0 0" rpy="${-pi/2} 0 ${-pi/2}"/>-->
  <!--<parent link="camera_link"/>-->
  <!--<child link="camera_link_optical"/>-->
  <!--</joint>-->
  <!--<link name="camera_link_optical">-->
  <!--</link>-->
  <transmission name="tran0">
    <type>transmission_interface/SimpleTransmission</type>
    <joint name="joint0">
      <hardwareInterface>hardware_interface/EffortJointInterface</hardwareInterface>
    </joint>
    <actuator name="motor0">
      <hardwareInterface>hardware_interface/EffortJointInterface</hardwareInterface>
      <mechanicalReduction>1</mechanicalReduction>
    </actuator>
  </transmission>
  <transmission name="tran1">
    <type>transmission_interface/SimpleTransmission</type>
    <joint name="joint1">
      <hardwareInterface>hardware_interface/EffortJointInterface</hardwareInterface>
    </joint>
    <actuator name="motor1">
      <hardwareInterface>hardware_interface/EffortJointInterface</hardwareInterface>
      <mechanicalReduction>1</mechanicalReduction>
    </actuator>
  </transmission>
  <transmission name="tran2">
    <type>transmission_interface/SimpleTransmission</type>
    <joint name="joint2">
      <hardwareInterface>hardware_interface/EffortJointInterface</hardwareInterface>
    </joint>
    <actuator name="motor2">
      <hardwareInterface>hardware_interface/EffortJointInterface</hardwareInterface>
      <mechanicalReduction>1</mechanicalReduction>
    </actuator>
  </transmission>
</robot>

