<?xml version="1.0" ?>
<!-- =================================================================================== -->
<!-- |    This document was autogenerated by xacro from planar4dof.xacro               | -->
<!-- |    EDITING THIS FILE BY HAND IS NOT RECOMMENDED                                 | -->
<!-- =================================================================================== -->
<!-- Planar 4DoF robot (based on Revolute-Revolute Manipulator) -->
<robot name="planar4dof" xmlns:xacro="http://www.ros.org/wiki/xacro">
    <material name="black">
        <color rgba="0.0 0.0 0.0 1.0"/>
    </material>
    <material name="blue">
        <color rgba="0.0 0.0 0.8 1.0"/>
    </material>
    <material name="green">
        <color rgba="0.0 0.8 0.0 1.0"/>
    </material>
    <material name="grey">
        <color rgba="0.2 0.2 0.2 1.0"/>
    </material>
    <material name="orange">
        <color rgba="1.0 0.423529411765 0.0392156862745 1.0"/>
    </material>
    <material name="brown">
        <color rgba="0.870588235294 0.811764705882 0.764705882353 1.0"/>
    </material>
    <material name="red">
        <color rgba="0.8 0.0 0.0 1.0"/>
    </material>
    <material name="white">
        <color rgba="1.0 1.0 1.0 1.0"/>
    </material>
    <!-- Used for fixing robot to Gazebo 'base_link' -->
    <link name="world"/>
    <!--<joint name="fixed" type="fixed">-->
    <!--<parent link="world"/>-->
    <!--<child link="link1"/>-->
    <!--<origin xyz="0 0 ${base_z}" rpy="0 0 0"/>-->
    <!--</joint>-->
    <joint name="fixed" type="fixed">
        <parent link="world"/>
        <child link="base_link"/>
        <origin rpy="0 0 0" xyz="0 0 0.0"/>
    </joint>
    <link name="base_link">
        <collision>
            <origin rpy="0 0 0" xyz="0 0 0.015"/>
            <geometry>
                <cylinder length="0.03" radius="0.01"/>
            </geometry>
        </collision>
        <visual>
            <origin rpy="0 0 0" xyz="0 0 0.015"/>
            <geometry>
                <cylinder length="0.03" radius="0.01"/>
            </geometry>
            <material name="black"/>
        </visual>
        <inertial>
            <origin rpy="0 0 0" xyz="0 0 0.015"/>
            <mass value="1.47969013984"/>
            <inertia ixx="0.000147969013984" ixy="0.0" ixz="0.0"
                     iyy="0.000147969013984" iyz="0.0" izz="7.3984506992e-05"/>
        </inertial>
    </link>
<!--    <joint name="joint0" type="continuous">-->
    <joint name="joint0" type="revolute">
        <parent link="base_link"/>
        <child link="coupler0"/>
        <origin rpy="0 0 0" xyz="0 0 0.04"/>
        <limit effort="100.0" lower="-2.18" upper="2.18" velocity="0.5"/>
        <axis xyz="0 0 1"/>
        <dynamics damping="0.7"/>
    </joint>
    <link name="coupler0">
        <collision>
            <origin rpy="0 0 0" xyz="0 0 0"/>
            <geometry>
                <!--<sphere radius="${radius_axel}"/>-->
                <cylinder length="0.05" radius="0.045"/>
            </geometry>
        </collision>
        <visual>
            <origin rpy="0 0 0" xyz="0 0 0"/>
            <geometry>
                <!--<sphere radius="${radius_axel}"/>-->
                <cylinder length="0.05" radius="0.045"/>
            </geometry>
            <material name="white"/>
        </visual>
        <inertial>
            <origin rpy="0 0 0" xyz="0 0 0"/>
            <mass value="0.001"/>
            <inertia ixx="0.001" ixy="0.0" ixz="0.0" iyy="0.001" iyz="0.0"
                     izz="0.001"/>
        </inertial>
    </link>
    <joint name="coupler_joint0" type="fixed">
        <parent link="coupler0"/>
        <child link="link1"/>
        <origin rpy="0 0 0" xyz="0 0 0"/>
    </joint>
    <!-- Base Link -->
    <link name="link1">
        <collision>
            <origin rpy="1.57079632679 0 1.57079632679" xyz="0.105 0 0"/>
            <geometry>
                <cylinder length="0.21" radius="0.025"/>
            </geometry>
        </collision>
        <visual>
            <origin rpy="1.57079632679 0 1.57079632679" xyz="0.105 0 0"/>
            <geometry>
                <cylinder length="0.21" radius="0.025"/>
            </geometry>
            <material name="blue"/>
        </visual>
        <inertial>
            <origin rpy="1.57079632679 0 1.57079632679" xyz="0.105 0 0"/>
            <mass value="0.890641517293"/>
            <inertia ixx="0.00341227031313" ixy="0.0" ixz="0.0"
                     iyy="0.00341227031313" iyz="0.0" izz="0.000278325474154"/>
        </inertial>
    </link>
    <!--<joint name="joint1" type="continuous">-->
    <!--<parent link="link1"/>-->
    <!--<child link="link2"/>-->
    <!--<origin xyz="${height1 + axel_offset} 0 0" rpy="0 0 0"/>-->
    <!--<axis xyz="0 0 1"/>-->
    <!--<dynamics damping="0.7"/>-->
    <!--</joint>-->
    <joint name="joint1" type="revolute">
        <parent link="link1"/>
        <child link="coupler1"/>
        <origin rpy="0 0 0" xyz="0.245 0 0"/>
        <limit effort="100.0" lower="-2.18" upper="2.18" velocity="0.5"/>
        <axis xyz="0 0 1"/>
        <dynamics damping="0.7"/>
    </joint>
    <link name="coupler1">
        <collision>
            <origin rpy="0 0 0" xyz="0 0 0"/>
            <geometry>
                <cylinder length="0.05" radius="0.045"/>
            </geometry>
        </collision>
        <visual>
            <origin rpy="0 0 0" xyz="0 0 0"/>
            <geometry>
                <cylinder length="0.05" radius="0.045"/>
            </geometry>
            <material name="white"/>
        </visual>
        <inertial>
            <origin rpy="0 0 0" xyz="0 0 0"/>
            <mass value="0.001"/>
            <inertia ixx="1.0" ixy="0.0" ixz="0.0" iyy="1.0" iyz="0.0"
                     izz="1.0"/>
        </inertial>
    </link>
    <joint name="coupler_joint1" type="fixed">
        <parent link="coupler1"/>
        <child link="link2"/>
        <origin rpy="0 0 0" xyz="0.035 0 0"/>
    </joint>
    <!--Middle Link-->
    <link name="link2">
        <collision>
            <origin rpy="1.57079632679 0 1.57079632679" xyz="0.065 0 0"/>
            <geometry>
                <cylinder length="0.13" radius="0.025"/>
            </geometry>
        </collision>
        <visual>
            <origin rpy="1.57079632679 0 1.57079632679" xyz="0.065 0 0"/>
            <geometry>
                <cylinder length="0.13" radius="0.025"/>
            </geometry>
            <material name="blue"/>
        </visual>
        <inertial>
            <origin rpy="1.57079632679 0 1.57079632679" xyz="0.065 0 0"/>
            <mass value="0.551349510705"/>
            <inertia ixx="0.000862632255291" ixy="0.0" ixz="0.0"
                     iyy="0.000862632255291" iyz="0.0"
                     izz="0.000172296722095"/>
        </inertial>
    </link>
    <!--<joint name="joint2" type="continuous">-->
    <!--<parent link="link2"/>-->
    <!--<child link="link3"/>-->
    <!--<origin xyz="${height2 + axel_offset*2} 0.1 0.1" rpy="0 0 0"/>-->
    <!--<axis xyz="0 0 1"/>-->
    <!--<dynamics damping="0.7"/>-->
    <!--</joint>-->
    <joint name="joint2" type="revolute">
        <parent link="link2"/>
        <child link="coupler2"/>
        <origin rpy="0 0 0" xyz="0.165 0 0"/>
        <limit effort="100.0" lower="-2.18" upper="2.18" velocity="0.5"/>
        <axis xyz="0 0 1"/>
        <dynamics damping="0.7"/>
    </joint>
    <link name="coupler2">
        <collision>
            <origin rpy="0 0 0" xyz="0 0 0"/>
            <geometry>
                <cylinder length="0.05" radius="0.045"/>
            </geometry>
        </collision>
        <visual>
            <origin rpy="0 0 0" xyz="0 0 0"/>
            <geometry>
                <cylinder length="0.05" radius="0.045"/>
            </geometry>
            <material name="white"/>
        </visual>
        <inertial>
            <origin rpy="0 0 0" xyz="0 0 0"/>
            <mass value="0.001"/>
            <inertia ixx="1.0" ixy="0.0" ixz="0.0" iyy="1.0" iyz="0.0"
                     izz="1.0"/>
        </inertial>
    </link>
    <joint name="coupler_joint2" type="fixed">
        <parent link="coupler2"/>
        <child link="link3"/>
        <origin rpy="0 0 0" xyz="0.035 0 0"/>
    </joint>
    <!--Top Link-->
    <link name="link3">
        <collision>
            <origin rpy="1.57079632679 0 1.57079632679" xyz="0.055 0 0"/>
            <geometry>
                <cylinder length="0.11" radius="0.025"/>
            </geometry>
        </collision>
        <visual>
            <origin rpy="1.57079632679 0 1.57079632679" xyz="0.055 0 0"/>
            <geometry>
                <cylinder length="0.11" radius="0.025"/>
            </geometry>
            <material name="blue"/>
        </visual>
        <inertial>
            <origin rpy="1.57079632679 0 1.57079632679" xyz="0.055 0 0"/>
            <mass value="0.466526509058"/>
            <inertia ixx="0.000543308997007" ixy="0.0" ixz="0.0"
                     iyy="0.000543308997007" iyz="0.0"
                     izz="0.000145789534081"/>
        </inertial>
    </link>
    <joint name="joint3" type="revolute">
        <parent link="link3"/>
        <child link="coupler3"/>
        <origin rpy="0 0 0" xyz="0.145 0 0"/>
        <limit effort="100.0" lower="-2.18" upper="2.18" velocity="0.5"/>
        <axis xyz="0 0 1"/>
        <dynamics damping="0.7"/>
    </joint>
    <link name="coupler3">
        <collision>
            <origin rpy="0 0 0" xyz="0 0 0"/>
            <geometry>
                <cylinder length="0.05" radius="0.045"/>
            </geometry>
        </collision>
        <visual>
            <origin rpy="0 0 0" xyz="0 0 0"/>
            <geometry>
                <cylinder length="0.05" radius="0.045"/>
            </geometry>
            <material name="white"/>
        </visual>
        <inertial>
            <origin rpy="0 0 0" xyz="0 0 0"/>
            <mass value="0.001"/>
            <inertia ixx="1.0" ixy="0.0" ixz="0.0" iyy="1.0" iyz="0.0"
                     izz="1.0"/>
        </inertial>
    </link>
    <joint name="coupler_joint3" type="fixed">
        <parent link="coupler3"/>
        <child link="link4"/>
        <origin rpy="0 0 0" xyz="0.035 0 0"/>
    </joint>
    <!--Top Link-->
    <link name="link4">
        <collision>
            <origin rpy="1.57079632679 0 1.57079632679" xyz="0.04 0 0"/>
            <geometry>
                <cylinder length="0.08" radius="0.025"/>
            </geometry>
        </collision>
        <visual>
            <origin rpy="1.57079632679 0 1.57079632679" xyz="0.04 0 0"/>
            <geometry>
                <cylinder length="0.08" radius="0.025"/>
            </geometry>
            <material name="blue"/>
        </visual>
        <inertial>
            <origin rpy="1.57079632679 0 1.57079632679" xyz="0.04 0 0"/>
            <mass value="0.339292006588"/>
            <inertia ixx="0.000233970112876" ixy="0.0" ixz="0.0"
                     iyy="0.000233970112876" iyz="0.0"
                     izz="0.000106028752059"/>
        </inertial>
    </link>
    <joint name="gripper_joint" type="fixed">
        <parent link="link4"/>
        <child link="gripper"/>
        <origin rpy="0 0 0" xyz="0.08 0 0"/>
    </joint>
    <link name="gripper">
        <visual>
            <origin rpy="1.57079632679 0 1.57079632679" xyz="0.0075 0 0"/>
            <geometry>
                <box size="0.16 0.025 0.015"/>
            </geometry>
            <material name="white"/>
        </visual>
        <visual>
            <origin rpy="1.57079632679 0 1.57079632679" xyz="0.0575 0.07 0"/>
            <geometry>
                <box size="0.02 0.025 0.085"/>
            </geometry>
            <material name="white"/>
        </visual>
        <visual>
            <origin rpy="1.57079632679 0 1.57079632679" xyz="0.0575 -0.07 0"/>
            <geometry>
                <box size="0.02 0.025 0.085"/>
            </geometry>
            <material name="white"/>
        </visual>
        <collision>
            <origin rpy="1.57079632679 0 1.57079632679" xyz="0.0075 0 0"/>
            <geometry>
                <box size="0.16 0.025 0.015"/>
            </geometry>
            <material name="white"/>
        </collision>
        <collision>
            <origin rpy="1.57079632679 0 1.57079632679" xyz="0.0575 0.07 0"/>
            <geometry>
                <box size="0.02 0.025 0.085"/>
            </geometry>
            <material name="white"/>
        </collision>
        <collision>
            <origin rpy="1.57079632679 0 1.57079632679" xyz="0.0575 -0.07 0"/>
            <geometry>
                <box size="0.02 0.025 0.085"/>
            </geometry>
            <material name="white"/>
        </collision>
        <inertial>
            <origin rpy="0 0 0" xyz="0 0 0"/>
            <mass value="0.1"/>
            <inertia ixx="1.0" ixy="0.0" ixz="0.0" iyy="1.0" iyz="0.0"
                     izz="1.0"/>
        </inertial>
    </link>
    <joint name="gripper_center_joint" type="fixed">
        <parent link="gripper"/>
        <child link="gripper_center"/>
        <origin rpy="0 0 0" xyz="0.06 0 0"/>
    </joint>
    <link name="gripper_center">
        <!--<visual>-->
        <!--<origin xyz="0 0 0" rpy="0 0 0"/>-->
        <!--<geometry>-->
        <!--<cylinder length="${height_axel}" radius="${radius_axel}"/>-->
        <!--</geometry>-->
        <!--<material name="white"/>-->
        <!--</visual>-->
        <inertial>
            <origin rpy="0 0 0" xyz="0 0 0"/>
            <mass value="0.001"/>
            <inertia ixx="0.001" ixy="0.0" ixz="0.0" iyy="0.001" iyz="0.0"
                     izz="0.001"/>
        </inertial>
    </link>
    <transmission name="tran0">
        <type>transmission_interface/SimpleTransmission</type>
        <joint name="joint0">
            <hardwareInterface>hardware_interface/EffortJointInterface
            </hardwareInterface>
        </joint>
        <actuator name="motor0">
            <hardwareInterface>hardware_interface/EffortJointInterface
            </hardwareInterface>
            <mechanicalReduction>1</mechanicalReduction>
        </actuator>
    </transmission>
    <transmission name="tran1">
        <type>transmission_interface/SimpleTransmission</type>
        <joint name="joint1">
            <hardwareInterface>hardware_interface/EffortJointInterface
            </hardwareInterface>
        </joint>
        <actuator name="motor1">
            <hardwareInterface>hardware_interface/EffortJointInterface
            </hardwareInterface>
            <mechanicalReduction>1</mechanicalReduction>
        </actuator>
    </transmission>
    <transmission name="tran2">
        <type>transmission_interface/SimpleTransmission</type>
        <joint name="joint2">
            <hardwareInterface>hardware_interface/EffortJointInterface
            </hardwareInterface>
        </joint>
        <actuator name="motor2">
            <hardwareInterface>hardware_interface/EffortJointInterface
            </hardwareInterface>
            <mechanicalReduction>1</mechanicalReduction>
        </actuator>
    </transmission>
    <transmission name="tran3">
        <type>transmission_interface/SimpleTransmission</type>
        <joint name="joint3">
            <hardwareInterface>hardware_interface/EffortJointInterface
            </hardwareInterface>
        </joint>
        <actuator name="motor3">
            <hardwareInterface>hardware_interface/EffortJointInterface
            </hardwareInterface>
            <mechanicalReduction>1</mechanicalReduction>
        </actuator>
    </transmission>
</robot>

